Workbook

Sheet Sheet1
A1: RTL | B1: pin | C1: SoMネット名 | D1: FT601ネット名
A2: ft601_clk | B2: K5 | C2: K5_IOT63B | D2: FT601_CLK
A3: ft601_txe_n | B3: G2 | C3: G2_IOR24A_40P | D3: FT601_TXE
A4: ft601_rxf_n | B4: K4 | C4: K4_IOR22B_40P | D4: FT601_RXF
A5: ft601_siwu_n | B5: J4 | C5: J4_IOR22A_40P | D5: FT601_SIWU
A6: ft601_wr_n | B6: K2 | C6: K2_IOR20B_40P | D6: FT601_WR
A7: ft601_rd_n | B7: K1 | C7: K1_IOR20A_40P | D7: FT601_RD
A8: ft601_oe_n | B8: L1 | C8: L1_IOR18B_40P | D8: FT601_OE
A9: ft601_gpio[0] | B9: H1 | C9: G1_IOR24B_40P | D9: FT601_GPIO0
A10: ft601_gpio[1] | B10: H2 | C10: L4_IOR31A_40P | D10: FT601_GPIO1
A11: ft601_be[0] | B11: J1 | C11: J1_IOR33A_40P | D11: FT601_BE0
A12: ft601_be[1] | B12: L3 | C12: L3_IOR31B_40P | D12: FT601_BE1
... A48: ft601_wakeup | B48: H4 | C48: H4_IOB89B_40P | D48: FT601_WAKEUP

Sheet Sheet2
A1: No. | B1: conn | C1: pin | D1: FPGA | E1: NAME | F1: bank | G1: attr | H1: Voltage | I1: RTL | J1: LOC
A2: 1 | B2: J3 | C2: 2 | E2: GND | F2: 0 | I2: =_xlfn.XLOOKUP(D2, Sheet1!B$2:B$48, Sheet1!A$2:A$48, "") | J2: =IF(I2<>"","IO_LOC """&I2&""" "&D2&";", "")
A3: 12 | B3: J3 | C3: 24 | E3: VCCIO0_1 | I3: =_xlfn.XLOOKUP(D3, Sheet1!B$2:B$48, Sheet1!A$2:A$48, "") | J3: =IF(I3<>"","IO_LOC """&I3&""" "&D3&";", "")
A4: 13 | B4: J3 | C4: 26 | E4: VCCIO0_1 | I4: =_xlfn.XLOOKUP(D4, Sheet1!B$2:B$48, Sheet1!A$2:A$48, "") | J4: =IF(I4<>"","IO_LOC """&I4&""" "&D4&";", "")
A5: 14 | B5: J3 | C5: 28 | E5: GND | I5: =_xlfn.XLOOKUP(D5, Sheet1!B$2:B$48, Sheet1!A$2:A$48, "") | J5: =IF(I5<>"","IO_LOC """&I5&""" "&D5&";", "")
A6: 25 | B6: J3 | C6: 50 | E6: GND | I6: =_xlfn.XLOOKUP(D6, Sheet1!B$2:B$48, Sheet1!A$2:A$48, "") | J6: =IF(I6<>"","IO_LOC """&I6&""" "&D6&";", "")
A7: 30 | B7: J3 | C7: 60 | E7: GND | I7: =_xlfn.XLOOKUP(D7, Sheet1!B$2:B$48, Sheet1!A$2:A$48, "") | J7: =IF(I7<>"","IO_LOC """&I7&""" "&D7&";", "")
A8: 31 | B8: J3 | C8: 1 | E8: GND | F8: 0 | I8: =_xlfn.XLOOKUP(D8, Sheet1!B$2:B$48, Sheet1!A$2:A$48, "") | J8: =IF(I8<>"","IO_LOC """&I8&""" "&D8&";", "")
A9: 38 | B9: J3 | C9: 15 | E9: GND | I9: =_xlfn.XLOOKUP(D9, Sheet1!B$2:B$48, Sheet1!A$2:A$48, "") | J9: =IF(I9<>"","IO_LOC """&I9&""" "&D9&";", "")
A10: 44 | B10: J3 | C10: 27 | E10: GND | I10: =_xlfn.XLOOKUP(D10, Sheet1!B$2:B$48, Sheet1!A$2:A$48, "") | J10: =IF(I10<>"","IO_LOC """&I10&""" "&D10&";", "")
A11: 45 | B11: J3 | C11: 29 | E11: VCCIO6_7 | I11: =_xlfn.XLOOKUP(D11, Sheet1!B$2:B$48, Sheet1!A$2:A$48, "") | J11: =IF(I11<>"","IO_LOC """&I11&""" "&D11&";", "")
A12: 46 | B12: J3 | C12: 31 | E12: VCCIO6_7 | I12: =_xlfn.XLOOKUP(D12, Sheet1!B$2:B$48, Sheet1!A$2:A$48, "") | J12: =IF(I12<>"","IO_LOC """&I12&""" "&D12&";", "")
A13: 53 | B13: J3 | C13: 45 | E13: GND | I13: =_xlfn.XLOOKUP(D13, Sheet1!B$2:B$48, Sheet1!A$2:A$48, "") | J13: =IF(I13<>"","IO_LOC """&I13&""" "&D13&";", "")
A14: 60 | B14: J3 | C14: 59 | E14: GND | I14: =_xlfn.XLOOKUP(D14, Sheet1!B$2:B$48, Sheet1!A$2:A$48, "") | J14: =IF(I14<>"","IO_LOC """&I14&""" "&D14&";", "")
A15: 61 | B15: J4 | C15: 2 | E15: VCCIO2_3 | I15: =_xlfn.XLOOKUP(D15, Sheet1!B$2:B$48, Sheet1!A$2:A$48, "") | J15: =IF(I15<>"","IO_LOC """&I15&""" "&D15&";", "")
A16: 62 | B16: J4 | C16: 4 | E16: VCCIO2_3 | I16: =_xlfn.XLOOKUP(D16, Sheet1!B$2:B$48, Sheet1!A$2:A$48, "") | J16: =IF(I16<>"","IO_LOC """&I16&""" "&D16&";", "")
A17: 79 | B17: J4 | C17: 38 | E17: 1.8V | I17: =_xlfn.XLOOKUP(D17, Sheet1!B$2:B$48, Sheet1!A$2:A$48, "") | J17: =IF(I17<>"","IO_LOC """&I17&""" "&D17&";", "")
A18: 80 | B18: J4 | C18: 40 | E18: 1.8V | I18: =_xlfn.XLOOKUP(D18, Sheet1!B$2:B$48, Sheet1!A$2:A$48, "") | J18: =IF(I18<>"","IO_LOC """&I18&""" "&D18&";", "")
A19: 81 | B19: J4 | C19: 42 | E19: 2.5V | I19: =_xlfn.XLOOKUP(D19, Sheet1!B$2:B$48, Sheet1!A$2:A$48, "") | J19: =IF(I19<>"","IO_LOC """&I19&""" "&D19&";", "")
A20: 82 | B20: J4 | C20: 44 | E20: 2.5V | I20: =_xlfn.XLOOKUP(D20, Sheet1!B$2:B$48, Sheet1!A$2:A$48, "") | J20: =IF(I20<>"","IO_LOC """&I20&""" "&D20&";", "")
... A29: 91 | B29: J4 | C29: 1 | E29: GND | I29: =_xlfn.XLOOKUP(D29, Sheet1!B$2:B$48, Sheet1!A$2:A$48, "") | J29: =IF(I29<>"","IO_LOC """&I29&""" "&D29&";", "")
A30: 97 | B30: J4 | C30: 13 | D30: D8 | E30: D8_RECONFIG | F30: 5 | H30: 3.3 | I30: =_xlfn.XLOOKUP(D30, Sheet1!B$2:B$48, Sheet1!A$2:A$48, "") | J30: =IF(I30<>"","IO_LOC """&I30&""" "&D30&";", "")
A31: 100 | B31: J4 | C31: 19 | E31: GND | I31: =_xlfn.XLOOKUP(D31, Sheet1!B$2:B$48, Sheet1!A$2:A$48, "") | J31: =IF(I31<>"","IO_LOC """&I31&""" "&D31&";", "")
A32: 105 | B32: J4 | C32: 29 | E32: GND | I32: =_xlfn.XLOOKUP(D32, Sheet1!B$2:B$48, Sheet1!A$2:A$48, "") | J32: =IF(I32<>"","IO_LOC """&I32&""" "&D32&";", "")
A33: 111 | B33: J4 | C33: 41 | E33: GND | I33: =_xlfn.XLOOKUP(D33, Sheet1!B$2:B$48, Sheet1!A$2:A$48, "") | J33: =IF(I33<>"","IO_LOC """&I33&""" "&D33&";", "")
A34: 114 | B34: J4 | C34: 47 | E34: GND | I34: =_xlfn.XLOOKUP(D34, Sheet1!B$2:B$48, Sheet1!A$2:A$48, "") | J34: =IF(I34<>"","IO_LOC """&I34&""" "&D34&";", "")
A35: 117 | B35: J4 | C35: 53 | E35: GND | I35: =_xlfn.XLOOKUP(D35, Sheet1!B$2:B$48, Sheet1!A$2:A$48, "") | J35: =IF(I35<>"","IO_LOC """&I35&""" "&D35&";", "")
A36: 120 | B36: J4 | C36: 59 | E36: GND | I36: =_xlfn.XLOOKUP(D36, Sheet1!B$2:B$48, Sheet1!A$2:A$48, "")
A37: 56 | B37: J3 | C37: 51 | D37: C11 | E37: C11_IOL5A | F37: 6 | H37: 1.8 | I37: dip_sw[0] | J37: =IF(I37<>"","IO_LOC """&I37&""" "&D37&";", "") -> IO_LOC "dip_sw[0]" C11;
A38: 57 | B38: J3 | C38: 53 | D38: C10 | E38: C10_IOL5B | F38: 6 | H38: 1.8 | I38: dip_sw[1] | J38: =IF(I38<>"","IO_LOC """&I38&""" "&D38&";", "") -> IO_LOC "dip_sw[1]" C10;
A39: 73 | B39: J4 | C39: 26 | D39: J1 | E39: J1_IOR33A_40P | F39: 2 | G39: GCLK | H39: 1.8 | I39: =_xlfn.XLOOKUP(D39, Sheet1!B$2:B$48, Sheet1!A$2:A$48, "") -> ft601_be[0] | J39: =IF(I39<>"","IO_LOC """&I39&""" "&D39&";", "") -> IO_LOC "ft601_be[0]" J1;
A40: 72 | B40: J4 | C40: 24 | D40: L3 | E40: L3_IOR31B_40P | F40: 2 | G40: GCLK | H40: 1.8 | I40: =_xlfn.XLOOKUP(D40, Sheet1!B$2:B$48, Sheet1!A$2:A$48, "") -> ft601_be[1] | J40: =IF(I40<>"","IO_LOC """&I40&""" "&D40&";", "") -> IO_LOC "ft601_be[1]" L3;
A41: 71 | B41: J4 | C41: 22 | D41: L4 | E41: L4_IOR31A_40P | F41: 2 | G41: GCLK | H41: 1.8 | I41: =_xlfn.XLOOKUP(D41, Sheet1!B$2:B$48, Sheet1!A$2:A$48, "") -> ft601_be[2] | J41: =IF(I41<>"","IO_LOC """&I41&""" "&D41&";", "") -> IO_LOC "ft601_be[2]" L4;
A42: 70 | B42: J4 | C42: 20 | D42: G1 | E42: G1_IOR24B_40P | F42: 2 | H42: 1.8 | I42: =_xlfn.XLOOKUP(D42, Sheet1!B$2:B$48, Sheet1!A$2:A$48, "") -> ft601_be[3] | J42: =IF(I42<>"","IO_LOC """&I42&""" "&D42&";", "") -> IO_LOC "ft601_be[3]" G1;
A43: 5 | B43: J3 | C43: 10 | D43: K5 | E43: K5_IOT63B | F43: 0 | G43: GCLK | H43: 1.8 | I43: =_xlfn.XLOOKUP(D43, Sheet1!B$2:B$48, Sheet1!A$2:A$48, "") -> ft601_clk | J43: =IF(I43<>"","IO_LOC """&I43&""" "&D43&";", "") -> IO_LOC "ft601_clk" K5;
A44: 24 | B44: J3 | C44: 48 | D44: L11 | E44: L11_IOT11B | F44: 7 | H44: 1.8 | I44: =_xlfn.XLOOKUP(D44, Sheet1!B$2:B$48, Sheet1!A$2:A$48, "") -> ft601_data[0] | J44: =IF(I44<>"","IO_LOC """&I44&""" "&D44&";", "") -> IO_LOC "ft601_data[0]" L11;
A45: 23 | B45: J3 | C45: 46 | D45: K11 | E45: K11_IOT11A | F45: 7 | H45: 1.8 | I45: =_xlfn.XLOOKUP(D45, Sheet1!B$2:B$48, Sheet1!A$2:A$48, "") -> ft601_data[1] | J45: =IF(I45<>"","IO_LOC """&I45&""" "&D45&";", "") -> IO_LOC "ft601_data[1]" K11;
A46: 11 | B46: J3 | C46: 22 | D46: G5 | E46: G5_IOT72B | F46: 0 | H46: 1.8 | I46: =_xlfn.XLOOKUP(D46, Sheet1!B$2:B$48, Sheet1!A$2:A$48, "") -> ft601_data[10] | J46: =IF(I46<>"","IO_LOC """&I46&""" "&D46&";", "") -> IO_LOC "ft601_data[10]" G5;
A47: 10 | B47: J3 | C47: 20 | D47: F5 | E47: F5_IOT72A | F47: 0 | H47: 1.8 | I47: =_xlfn.XLOOKUP(D47, Sheet1!B$2:B$48, Sheet1!A$2:A$48, "") -> ft601_data[11] | J47: =IF(I47<>"","IO_LOC """&I47&""" "&D47&";", "") -> IO_LOC "ft601_data[11]" F5;
A48: 9 | B48: J3 | C48: 18 | D48: G8 | E48: G8_IOT68B | F48: 0 | H48: 1.8 | I48: =_xlfn.XLOOKUP(D48, Sheet1!B$2:B$48, Sheet1!A$2:A$48, "") -> ft601_data[12] | J48: =IF(I48<>"","IO_LOC """&I48&""" "&D48&";", "") -> IO_LOC "ft601_data[12]" G8;
...
